Workbook

Sheet README
A1: Bakery Price Import Template — FILLED (Aug 2026)
A3: Purpose | B3: Upload file for the Bakery counting app price import (Ticket 8). One row per item code.
A4: Source document | B4: Code 206 Bakery — official monthly price confirmation, Fresh Food Commercial.
B5: Signed: Associate Director Fresh Food / Director Commercial Fresh Food.
A6: Source files | B6: Bakery_Inventory_Adjustment-_FBK.xlsx + Bakery_Inventory_Adjustment-__2026_2_17_57.xlsx
A7: Price validity | B7: 1-31 August 2026
A8: Price basis | B8: EX VAT — instructed by Just, 14 Aug 2026.
A9: effectiveFrom | B9: 2026-08
A10: priceUom basis | B10: packtype from master_uom.json. Price is per ONE packtype unit.
B11: Verified: item 741756 = THB 3,200 per lang; master_uom pack_size 11,340 g. Consistent.
A13: !! VAT BASIS CHANGE | B13: master_cost.json today stores cost_vat = VAT-INCLUSIVE. 62 of 90 sampled items match IN VAT exactly; 0 match EX VAT.
B14: Importing EX VAT therefore DROPS every displayed cost by ~6.5% (1/1.07) with no user-visible explanation.
B15: DECISION NEEDED before import: (a) proceed EX VAT and restate, or (b) import IN VAT for continuity.
B16: Either way the app must persist a priceBasis field so the basis is never ambiguous again.
A18: !! STORE-SCOPED PRICES | B18: The Loose file applies only to stores 2 / 17 / 57. 26 codes appear in both files; 5 have different prices.
B19: The app has ONE global price per item and cannot model this. All-stores file used as the default.
B20: See the Conflicts sheet. Needs a decision with Phat.
A22: SCOPE | B22: BAKERY ONLY. Zero code overlap with the Packaging app item master.
B23: The Fresh Food Packaging non-trade price list (CGA / K.Sornmongkol) is still outstanding.
A25: Which cells to edit | B25: Sheet PriceImport, column K (New Price EX VAT) only — shaded yellow.
B26: Do NOT edit column A (Code) — it is the match key. Do not reorder or rename columns.
A27: Sheet guide | B27: PriceImport / NoPriceInSource / Conflicts / ChangeLog
A29: Cost label | B29: Estimated cost only — not an official value. RMS remains authoritative.

Sheet PriceImport
A1: PRICE IMPORT — edit column K only (yellow). Column A (Code) is the match key.
A2: Code | B2: Item Name | C2: Class | D2: In Item Master | E2: Countable | F2: priceUom | G2: Pack Size | H2: Sub UOM | I2: Current Cost (IN VAT) | J2: Current Cost EX VAT (derived) | K2: New Price EX VAT | L2: Delta % | M2: Status | N2: Supplier | O2: Source Doc | P2: effectiveFrom
A3: 125789 | B3: เบคอนคลาสสิค1กก.*4 | C3: 68 | D3: Y | E3: Y | F3: ลัง | G3: 4000 | H3: กรัม | I3: 1159.88 | J3: 1084 | K3: 1060 | L3: =IFERROR(IF(N(J3)=0,"",(K3-J3)/J3),"") -> -0.022140221 | M3: CHANGED | N3: บจก.เบทาโกรเกษตรอุตสาหกรรม | O3: Code 206 (all stores) | P3: 2026-08
A4: 125844 | B4: ไส้กรอกเวียนนาAคลาสสิค(ไก่ผสมหมู) | C4: 68 | D4: Y | E4: Y | F4: ถุง | G4: 4000 | H4: กรัม | I4: 470.8 | J4: 440 | K4: 420 | L4: =IFERROR(IF(N(J4)=0,"",(K4-J4)/J4),"") -> -0.045454545 | M4: CHANGED | N4: บจก.เบทาโกรเกษตรอุตสาหกรรม | O4: Code 206 (all stores) | P4: 2026-08
A5: 125892 | B5: แฮมหมูคลาสสิค1กก.*4 | C5: 68 | D5: Y | E5: Y | F5: ถุง | G5: 4000 | H5: กรัม | I5: 778.96 | J5: 728 | K5: 704 | L5: =IFERROR(IF(N(J5)=0,"",(K5-J5)/J5),"") -> -0.032967033 | M5: CHANGED | N5: บจก.เบทาโกรเกษตรอุตสาหกรรม | O5: Code 206 (all stores) | P5: 2026-08
A6: 154810 | B6: CITRI-FI200 FG 1*20 KG. | C6: 68 | D6: Y | E6: Y | F6: ลัง | G6: 20000 | H6: กรัม | I6: 11021 | J6: 10300 | K6: 9660 | L6: =IFERROR(IF(N(J6)=0,"",(K6-J6)/J6),"") -> -0.062135922 | M6: CHANGED | N6: บจก.ท็อปไฟลท์ อินเตอร์ฟู้ดส์ | O6: Code 206 (all stores) | P6: 2026-08
A7: 183153 | B7: ทิวลิปดาร์คชอคโกแลตชิพกลาง550กX2 | C7: - | D7: Y | E7: Y | F7: ถุง | G7: 1100 | H7: กรัม | I7: 243.74 | J7: 227.7944 | K7: 227.8 | L7: =IFERROR(IF(N(J7)=0,"",(K7-J7)/J7),"") -> 2.4583572e-05 | M7: CHANGED | N7: บจก.ซีโน-แปซิฟิค เทรดดิ้ง(ไทยแลนด์) | O7: Code 206 (all stores) | P7: 2026-08
A8: 204345 | B8: BF ผงฟู สูตรดับเบิลแอ็คติง 1 กก. | C8: - | D8: Y | E8: Y | F8: แพ็ค | G8: 10000 | H8: กรัม | I8: 120.61 | J8: 112.7196 | K8: 106.74 | L8: =IFERROR(IF(N(J8)=0,"",(K8-J8)/J8),"") -> -0.053048449 | M8: CHANGED | N8: บจก.ยูนิลีเวอร์ ไทย เทรดดิ้ง | O8: Code 206 (all stores) | P8: 2026-08
A9: 204492 | B9: แป้งมอยส์ชอคโกแลตมิกซ์ 20กก*1ถุง | C9: 68 | D9: Y | E9: Y | F9: ลัง | G9: 20000 | H9: กรัม | I9: 2709.24 | J9: 2532 | K9: 2480 | L9: =IFERROR(IF(N(J9)=0,"",(K9-J9)/J9),"") -> -0.020537125 | M9: CHANGED | N9: บจก.พูราโต๊ส(ประเทศไทย) | O9: Code 206 (all stores) | P9: 2026-08
A10: 213966 | B10: เอโร่เปลือกทาร์ตFZ18ชิ้น | C10: 68 | D10: Y | E10: Y | F10: ถุง | G10: 18 | H10: ชิ้น | I10: 48.89 | J10: 45.6916 | K10: 44.9511 | L10: =IFERROR(IF(N(J10)=0,"",(K10-J10)/J10),"") -> -0.01620648 | M10: CHANGED | N10: HANGZHOU GLOBAL FOOD SOLUTIONS CO.,LTD. | O10: Code 206 (all stores) | P10: 2026-08
A11: 295346 | B11: กล่องจตุรัส MAK10 200 ชิ้นX1 | C11: 68 | D11: Y | E11: Y | F11: กล่อง | G11: 200 | H11: ชิ้น | I11: 1778.34 | J11: 1662 | K11: 1270 | L11: =IFERROR(IF(N(J11)=0,"",(K11-J11)/J11),"") -> -0.23586041 | M11: CHANGED | N11: บจ.เทพวิมลพลาสติก | O11: Code 206 Loose (stores 2/17/57) | P11: 2026-08
A12: 303819 | B12: RM_กล่องขนมบรรจุ 3 ชิ้น 450ชุดX1 | C12: 68 | D12: Y | E12: Y | F12: กล่อง | G12: 1350 | H12: ชิ้น | I12: 1796 | J12: 1678.5047 | K12: 1282.5 | L12: =IFERROR(IF(N(J12)=0,"",(K12-J12)/J12),"") -> -0.23592707 | M12: CHANGED | N12: บจ.เทพวิมลพลาสติก | O12: Code 206 (all stores) | P12: 2026-08
A13: 338432 | B13: โดว์ขนมปังใบเตยมะพร้าว 80กx80ชนx1 | C13: 68 | D13: Y | E13: Y | F13: กล่อง | G13: 80 | H13: ชิ้น | I13: 929.37 | J13: 868.5701 | K13: 760 | L13: =IFERROR(IF(N(J13)=0,"",(K13-J13)/J13),"") -> -0.12499866 | M13: CHANGED | N13: บจก.อาร์ต ออฟ เบคกิ้ง | O13: Code 206 (all stores) | P13: 2026-08
A14: 399180 | B14: กล่อง6ช่องฝาในตัวMAK03-1 300ชนX1 | C14: 68 | D14: Y | E14: Y | F14: กล่อง | G14: 300 | H14: ชิ้น | I14: 1344.99 | J14: 1257 | K14: 960 | L14: =IFERROR(IF(N(J14)=0,"",(K14-J14)/J14),"") -> -0.23627685 | M14: CHANGED | N14: บจ.เทพวิมลพลาสติก | O14: Code 206 (all stores) | P14: 2026-08
A15: 752564 | B15: ไส้ไข่เค็มลาวากวน 1 กก. X 1 | C15: 68 | D15: Y | E15: Y | F15: ถุง | G15: 1000 | H15: กรัม | I15: 196.88 | J15: 184 | K15: 177 | L15: =IFERROR(IF(N(J15)=0,"",(K15-J15)/J15),"") -> -0.038043478 | M15: CHANGED | N15: บจ.เอเล็งจ์ ฟู้ด อินดัสทรีส์ (ประเทศไทย) | O15: Code 206 (all stores) | P15: 2026-08
A16: 791442 | B16: ไส้เนื้อเค้กกลิ่นวานิลลา1200ก.x6 | C16: 68 | D16: Y | E16: Y | F16: กล่อง | G16: 6 | H16: ถุง | I16: 1335.36 | J16: 1248 | K16: 1140 | L16: =IFERROR(IF(N(J16)=0,"",(K16-J16)/J16),"") -> -0.086538462 | M16: CHANGED | N16: บจก.ซันเมอรี่ | O16: Code 206 (all stores) | P16: 2026-08
A17: 820892 | B17: กล้วยหอมแช่แข็ง5กกX2ถุง | C17: 68 | D17: Y | E17: Y | F17: ลัง | G17: 10000 | H17: กรัม | I17: 385.2 | J17: 360 | K17: 330 | L17: =IFERROR(IF(N(J17)=0,"",(K17-J17)/J17),"") -> -0.083333333 | M17: CHANGED | N17: บริษัท คิง ฟรุทส์ จำกัด | O17: Code 206 (all stores) | P17: 2026-08
A18: 833556 | B18: แป้งขนมปัง CJ22.5กก.X1กระสอบ | C18: 68 | D18: Y | E18: Y | F18: กระสอบ | G18: 22500 | H18: กรัม | I18: 674.63 | J18: 630.4953 | K18: 610.95 | L18: =IFERROR(IF(N(J18)=0,"",(K18-J18)/J18),"") -> -0.030999914 | M18: CHANGED | N18: บจก.คอนเนค เอเชีย อินเตอร์ฟู้ด | O18: Code 206 (all stores) | P18: 2026-08
A19: 833557 | B19: แป้งเค้กCJ22.5กก.X1กระสอบ | C19: 68 | D19: Y | E19: Y | F19: กระสอบ | G19: 22500 | H19: กรัม | I19: 799.29 | J19: 747 | K19: 725.15 | L19: =IFERROR(IF(N(J19)=0,"",(K19-J19)/J19),"") -> -0.029250335 | M19: CHANGED | N19: บจก.คอนเนค เอเชีย อินเตอร์ฟู้ด | O19: Code 206 (all stores) | P19: 2026-08
A20: 833558 | B20: แป้งอเนกประสงค์CJ22.5กก.X1กระสอบ | C20: 68 | D20: Y | E20: Y | F20: กระสอบ | G20: 22500 | H20: กรัม | I20: 640.39 | J20: 598.4953 | K20: 581.25 | L20: =IFERROR(IF(N(J20)=0,"",(K20-J20)/J20),"") -> -0.028814428 | M20: CHANGED | N20: บจก.คอนเนค เอเชีย อินเตอร์ฟู้ด | O20: Code 206 (all stores) | P20: 2026-08
... A31: 974289 | B31: เนื้อมะพร้าวแช่แข็งแบบเส้น1กก.X1 | C31: 68 | D31: Y | E31: Y | F31: ถุง | G31: 1000 | H31: กรัม | I31: 105.61 | J31: 98.7009 | K31: 131.9 | L31: =IFERROR(IF(N(J31)=0,"",(K31-J31)/J31),"") -> 0.33636066 | M31: CHANGED | N31: บมจ. เซ็ปเป้ | O31: Code 206 (all stores) | P31: 2026-08
A32: 155074 | B32: คอร์นมิกซ์ 10กก.*1 | C32: 68 | D32: Y | E32: Y | F32: ลัง | G32: 10 | H32: กิโลกรัม | K32: 1790 | L32: =IFERROR(IF(N(J32)=0,"",(K32-J32)/J32),"") | M32: NEW - no existing cost record | N32: บมจ.เคซีจี คอร์ปอเรชั่น | O32: Code 206 (all stores) | P32: 2026-08
A33: 155110 | B33: แป้งไรย์ชนิดละเอียด 5กก.*1 | C33: 68 | D33: Y | E33: Y | F33: ลัง | G33: 5 | H33: กิโลกรัม | K33: 506 | L33: =IFERROR(IF(N(J33)=0,"",(K33-J33)/J33),"") | M33: NEW - no existing cost record | N33: บมจ.เคซีจี คอร์ปอเรชั่น | O33: Code 206 (all stores) | P33: 2026-08
A34: 155112 | B34: นันแดรี่วิปปิ้งครีม1000ซีซี*12 | C34: 68 | D34: Y | E34: Y | F34: ลัง | G34: 12 | H34: กระป๋อง | K34: 1478 | L34: =IFERROR(IF(N(J34)=0,"",(K34-J34)/J34),"") | M34: NEW - no existing cost record | N34: บริษัท เคซีจี คอร์ปอเรชั่น จำกัด | O34: Code 206 (all stores) | P34: 2026-08
A35: 155191 | B35: เรดดี้เจลนิวทรอล 12กระป๋อง*1กก. | C35: 68 | D35: Y | E35: Y | F35: ลัง | G35: 12 | H35: กระป๋อง | K35: 1082.4 | L35: =IFERROR(IF(N(J35)=0,"",(K35-J35)/J35),"") | M35: NEW - no existing cost record | N35: บมจ.เคซีจี คอร์ปอเรชั่น | O35: Code 206 (all stores) | P35: 2026-08
A36: 155218 | B36: เอสพีโกลด์ 20กก.*1 | C36: 68 | D36: Y | E36: Y | F36: ลัง | G36: 20 | H36: กิโลกรัม | K36: 2230 | L36: =IFERROR(IF(N(J36)=0,"",(K36-J36)/J36),"") | M36: NEW - no existing cost record | N36: บจก.แคลแทค | O36: Code 206 (all stores) | P36: 2026-08
A37: 197135 | B37: สติ๊กเกอร์ขนมปังกระเทียมFZ2000ใบ | C37: 68 | D37: Y | E37: Y | F37: ห่อ | G37: 2000 | H37: ใบ | K37: 7000 | L37: =IFERROR(IF(N(J37)=0,"",(K37-J37)/J37),"") | M37: NEW - no existing cost record | N37: บจก.พี.สเกล แอดเวอร์ไทซิ่ง | O37: Code 206 (all stores) | P37: 2026-08
A38: 205225 | B38: แป้งสาลีโกลด์เด้นมิกซ์ 22.5 กก*1 | C38: 68 | D38: Y | E38: Y | F38: กระสอบ | G38: 22.5 | H38: กิโลกรัม | K38: 748.6 | L38: =IFERROR(IF(N(J38)=0,"",(K38-J38)/J38),"") | M38: NEW - no existing cost record | N38: บริษัท แป้งสหการ จำกัด | O38: Code 206 (all stores) | P38: 2026-08
A39: 230753 | B39: ยูโรเปี้ยนมัฟฟิน มิกส์ 15กกX1 | C39: 68 | D39: Y | E39: Y | F39: ถุง | G39: 15 | H39: กิโลกรัม | K39: 1200 | L39: =IFERROR(IF(N(J39)=0,"",(K39-J39)/J39),"") | M39: NEW - no existing cost record | N39: บริษัท เบเกิลส์ (ไทยแลนด์) จำกัด | O39: Code 206 (all stores) | P39: 2026-08
A40: 230760 | B40: เชื้อเข้มข้นกลิ่นชอคโกแลต1กก. | C40: 68 | D40: Y | E40: Y | F40: กล่อง | G40: 1 | H40: กิโลกรัม | K40: 350 | L40: =IFERROR(IF(N(J40)=0,"",(K40-J40)/J40),"") | M40: NEW - no existing cost record | N40: บริษัท เบเกิลส์ (ไทยแลนด์) จำกัด | O40: Code 206 (all stores) | P40: 2026-08
A41: 230761 | B41: โคโค่มิกซ์1*10กก. | C41: 68 | D41: Y | E41: Y | F41: ถุง | G41: 10 | H41: กิโลกรัม | K41: 1500 | L41: =IFERROR(IF(N(J41)=0,"",(K41-J41)/J41),"") | M41: NEW - no existing cost record | N41: บริษัท เบเกิลส์ (ไทยแลนด์) จำกัด | O41: Code 206 (all stores) | P41: 2026-08
A42: 230806 | B42: เชื้อกลิ่นเนยวานิลลา 1กก. | C42: 68 | D42: Y | E42: Y | F42: กล่อง | G42: 1 | H42: กิโลกรัม | K42: 650 | L42: =IFERROR(IF(N(J42)=0,"",(K42-J42)/J42),"") | M42: NEW - no existing cost record | N42: บริษัท เบเกิลส์ (ไทยแลนด์) จำกัด | O42: Code 206 (all stores) | P42: 2026-08
A43: 230810 | B43: เชื้อเข้มข้นกลิ่นกาแฟ1กก. | C43: 68 | D43: Y | E43: Y | F43: กล่อง | G43: 1 | H43: กิโลกรัม | K43: 1100 | L43: =IFERROR(IF(N(J43)=0,"",(K43-J43)/J43),"") | M43: NEW - no existing cost record | N43: บริษัท เบเกิลส์ (ไทยแลนด์) จำกัด | O43: Code 206 (all stores) | P43: 2026-08
... A54: 901013 | B54: สโนว์ไลน์ เอส 11 1 กกX2ถุง | C54: 68 | D54: Y | E54: Y | F54: ลัง | G54: 2 | H54: กิโลกรัม | K54: 280 | L54: =IFERROR(IF(N(J54)=0,"",(K54-J54)/J54),"") | M54: NEW - no existing cost record | N54: บจก.พูราโต๊ส(ประเทศไทย) | O54: Code 206 (all stores) | P54: 2026-08
A55: 109830 | B55: คนอร์ พิซซ่าซอส 1000ก.X1 | C55: - | D55: Y | E55: Y | F55: ถุง | G55: 1000 | H55: กรัม | I55: 80.04 | J55: 74.8037 | L55: =IFERROR(IF(N(J55)=0,"",(K55-J55)/J55),"") -> -1 | M55: NO PRICE - use store retail cost | N55: เบิกในสโตร์ | O55: Code 206 (all stores) | P55: 2026-08
A56: 121586 | B56: เซพแพ็คสวีทเบเกอรีมายองเนส1000กX1 | C56: - | D56: Y | E56: Y | F56: ถุง | G56: 1000 | H56: กรัม | I56: 43.99 | J56: 41.1121 | L56: =IFERROR(IF(N(J56)=0,"",(K56-J56)/J56),"") -> -1 | M56: NO PRICE - use store retail cost | N56: เบิกในสโตร์ | O56: Code 206 (all stores) | P56: 2026-08
A57: 198368 | B57: ARO ไข่ไก่ เบอร์ 2 มีฝา 30 ฟอง | C57: - | D57: Y | E57: Y | F57: แผง | G57: 30 | H57: ฟอง | I57: 129.47 | J57: 121 | L57: =IFERROR(IF(N(J57)=0,"",(K57-J57)/J57),"") -> -1 | M57: NO PRICE - use store retail cost | N57: เบิกในสโตร์ | O57: Code 206 (all stores) | P57: 2026-08
A58: 202995 | B58: ลิน น้ำตาลไอซิ่ง900กรัม*1 | C58: - | D58: Y | E58: Y | F58: ถุง | G58: 900 | H58: กรัม | I58: 37.05 | J58: 34.6262 | L58: =IFERROR(IF(N(J58)=0,"",(K58-J58)/J58),"") -> -1 | M58: NO PRICE - use store retail cost | N58: ใช้ราคาทุนหน้าร้าน | O58: Code 206 Loose (stores 2/17/57) | P58: 2026-08
A59: 668317 | B59: เอโร่เกลือเสริมไอโอดีน 5กก.X1ถุง | C59: - | D59: Y | E59: Y | F59: กระสอบ | G59: 5000 | H59: กรัม | I59: 32.1 | J59: 30 | L59: =IFERROR(IF(N(J59)=0,"",(K59-J59)/J59),"") -> -1 | M59: NO PRICE - use store retail cost | N59: ใช้ราคาทุนหน้าร้าน | O59: Code 206 Loose (stores 2/17/57) | P59: 2026-08
A60: 800659 | B60: ฟอลคอน นมข้นจืด 1000มล.X12 | C60: - | D60: Y | E60: Y | F60: ลัง | G60: 12 | H60: กล่อง | I60: 673.85 | J60: 629.7664 | L60: =IFERROR(IF(N(J60)=0,"",(K60-J60)/J60),"") -> -1 | M60: NO PRICE - use store retail cost | N60: เบิกในสโตร์ | O60: Code 206 (all stores) | P60: 2026-08
...

Sheet NoPriceInSource
A1: Countable items with NO price in the Code 206 documents
A2: On the count screen but no confirmed price. Decision needed: priced elsewhere, or store-retail-cost category?
A4: Code | B4: Item Name | C4: Class | D4: packtype | E4: Pack Size | F4: Current Cost IN VAT
A5: 102136 | B5: AROเม็ดมะม่วงหิมพานต์ซีก 800 กรัม | C5: 833 | D5: ถุง | E5: 800 | F5: 187.25
A6: 104517 | B6: ฟอลคอน นมข้นจืด 375ก.X6กป | C6: 318 | D6: แพ็ค | E6: 6 | F6: 133.65
A7: 117474 | B7: เอโร่ ซอสมะเขือเทศ 1000กx1 | C7: 732 | D7: แพ็ค | E7: 1000 | F7: 23.22
A8: 117819 | B8: มินิครัวซองต์15กรัมX10 | C8: 78 | D8: ถุง | E8: 15
A9: 118069 | B9: ฟอลคอน นมข้นจืด 1000มล.X1กล | C9: 318 | D9: กล่อง | E9: 1000 | F9: 56.15
A10: 124406 | B10: เอโร่ผักรวมแช่แข็ง 1กกx10 | C10: 747 | D10: กล่อง | E10: 10000 | F10: 7.97
A11: 134440 | B11: เซพแพ็ค แซนวิชสเปรด 1 กก. | C11: 306 | D11: ถุง | E11: 1000 | F11: 58.85
A12: 154817 | B12: GOLDKORMIX MIX 1*10KG. | C12: 68 | D12: ลัง | E12: 10
A13: 154821 | B13: COMBICORN BREADMIX 1*10KG. | C13: 68 | D13: ลัง | E13: 10
A14: 155543 | B14: โอวีเทค 20กก.*1 | C14: 68 | D14: ลัง | E14: 20
A15: 162727 | B15: เอโร่ ซอสมะเขือเทศ 10กรัมx100ซอง | C15: 732 | D15: แพ็ค | E15: 100 | F15: 58.97
A16: 163806 | B16: มินิครัวซองต์ไส้กรอกหมูชีส40กX4ช | C16: 78 | D16: กล่อง | E16: 40
A17: 163882 | B17: มินิครัวซองต์แฮมชีส 30 ก X 4 ชิ้น | C17: 78 | D17: กล่อง | E17: 30
A18: 164221 | B18: AROมอสซาเรลล่าขูดเส้นแช่แข็ง1กก*1 | C18: 753 | D18: ชิ้น | E18: 1000 | F18: 232.18
A19: 185907 | B19: งาขาว ตราARO 500กรัมX6 | C19: 829 | D19: ถุง | E19: 3000 | F19: 350.96
A20: 185923 | B20: งาดำ ตราARO 500กX6 | C20: 829 | D20: ถุง | E20: 3000 | F20: 406.6
A21: 194079 | B21: ผักสลัดกรีนโอ๊ค (ไฮโดรฯ) แพค500ก. | C21: 718 | D21: แพ็ค | E21: 500 | F21: 58.85
A22: 199898 | B22: ครัวซองต์เนยสด 43 กรัมX4 | C22: 78 | D22: ถุง | E22: 4 | F22: 47.92
A23: 204428 | B23: แป้งโฮลวีตมิกซ์ตราปังทอง22.5กก.*1 | C23: 68 | D23: กระสอบ | E23: 22.5
A24: 229666 | B24: เอโร่ ข้าวโอ๊ต 1 กก.x1 | C24: 81 | D24: ถุง | E24: 1000 | F24: 53.5
A25: 230759 | B25: เชื้อเข้มข้นกลิ่นส้ม 1กก. | C25: 68 | D25: กล่อง | E25: 1
A26: 230762 | B26: แป้งขนมปังมันฝรั่ง1*10กก. | C26: 68 | D26: ถุง | E26: 10
A27: 230763 | B27: เชื้อเข้มข้นกลิ่นสตรอเบอรี่1กก. | C27: 68 | D27: ลัง | E27: 1
A28: 230807 | B28: INTER_แป้งสำเร็จรูปชิฟฟ่อน 15กก*1 | C28: 68 | D28: ถุง | E28: 15
A29: 230811 | B29: ผงสำเร็จคัสตาร์ด1*10กก. | C29: 68 | D29: ถุง | E29: 10
A30: 30069 | B30: AROมาร์การีน(เนยเหลือง) 15KG.*1 | C30: 68 | D30: ลัง | E30: 15
A31: 324363 | B31: มะเขือเทศท้อ กก. ละ | C31: 725 | D31: แพ็ค | E31: 1000 | F31: 25.68
A32: 339049 | B32: RM_กล่องฝาพับเรียบ 400 ชิ้น x 1 | C32: 68 | D32: กล่อง | E32: 400 | F32: 1622.12
A33: 714082 | B33: RM_สกิปปีพีนัทบัตเตอร์ 1กก.x6ชนx1 | C33: 78 | D33: กล่อง | E33: 6 | F33: 1531.2
A34: 785124 | B34: RM_สติ๊กเกอร์ครัวซองต์พีนัต300ช | C34: 78 | D34: กล่อง | E34: 300 | F34: 1765.5
A35: 802109 | B35: ถุงครัวซองต์1X1000 ใบ | C35: 68 | D35: ลัง | E35: 1000
A36: 803955 | B36: อัลมอนด์สไลซ์ 11.34 กกX1 | C36: 834 | D36: แพ็ค | E36: 11340 | F36: 3424
A37: 846983 | B37: ARO ปูอัดแช่แข็ง 1000ก.X1 | C37: 752 | D37: แพ็ค | E37: 1000 | F37: 116.63
A38: 849422 | B38: นิปปุ่นซอฟเบรคมิกซ์25กกX1กระสอบ | C38: 68 | D38: กระสอบ | E38: 25
A39: 859219 | B39: โมจิเบรดมิกซ์ 25 กก. X 1 กระสอบ | C39: 68 | D39: กระสอบ | E39: 25
A40: 860308 | B40: โคฟเวอร์ลิคออเร้นจ์โค้ตติ้ง1กกX10 | C40: 68 | D40: กล่อง | E40: 10
A41: 860309 | B41: โคฟเวอร์สตอร์เบอรี่โค้ตติ้ง1กกX10 | C41: 68 | D41: กล่อง | E41: 10
...

Sheet Conflicts
A1: Codes appearing in BOTH source files with DIFFERENT prices
A2: The Loose file applies only to stores 2/17/57. The app holds ONE global price per item. All-stores price used as default — confirm with Phat.
A4: Code | B4: Item Name | C4: All-stores EX VAT | D4: Loose (2/17/57) EX VAT | E4: Used in template | F4: Note
A5: 924802 | B5: ซอสมะเขือเทศเอโร่ 1กก.x12 | C5: 252 | D5: 260.4 | E5: 252 | F5: Genuine price difference between the two documents
A6: 213860 | B6: เอโร่เปลือกทาร์ตFZ18ชนX16 | C6: 716.6124 | D6: 691.8239 | E6: 716.6124 | F6: Genuine price difference between the two documents
A7: 204345 | B7: BF ผงฟู สูตรดับเบิลแอ็คติง 1 กก. | C7: 106.74 | D7: - | E7: 106.74 | F7: Loose file says store retail cost; all-stores file has a confirmed price
A8: 183153 | B8: ทิวลิปดาร์คชอคโกแลตชิพกลาง550กX2 | C8: 227.8 | D8: - | E8: 227.8 | F8: Loose file says store retail cost; all-stores file has a confirmed price
A9: 182866 | B9: เบคกิ้งโซดาตราเบสท์โอเดอร์500ก*1 | C9: 26 | D9: - | E9: 26 | F9: Loose file says store retail cost; all-stores file has a confirmed price
A11: Codes present in both files (any price): 26 — of which 5 differ.

Sheet ChangeLog
A1: Import summary — expected preview/confirm figures
A2: Formulas over PriceImport so counts stay true if rows are edited.
A4: Total rows in template | B4: =COUNTA(PriceImport!A3:A297) -> 295
A5: Countable (appear on count screen) | B5: =COUNTIF(PriceImport!E3:E297,"Y") -> 122
A6: Status: CHANGED | B6: =COUNTIF(PriceImport!M3:M297,"CHANGED") -> 29
A7: Status: Unchanged | B7: =COUNTIF(PriceImport!M3:M297,"Unchanged") -> 61
A8: Status: NEW (no existing cost record) | B8: =COUNTIF(PriceImport!M3:M297,"NEW*") -> 23
A9: Status: NO PRICE (store retail cost rule) | B9: =COUNTIF(PriceImport!M3:M297,"NO PRICE*") -> 38
A10: Status: Not countable | B10: =COUNTIF(PriceImport!M3:M297,"Not countable*") -> 144
A11: Not in data.json item master | B11: =COUNTIF(PriceImport!D3:D297,"N*") -> 7
A12: Rows with |delta| > 20% (review) | B12: =SUMPRODUCT((ABS(N(PriceImport!L3:L297))>0.2)*1) -> 19
A13: Countable items with NO price in source | B13: =COUNTA(NoPriceInSource!A5:A46) -> 42
A14: Cross-file price conflicts | B14: =COUNTA(Conflicts!A5:A9) -> 5
A16: Source: Code 206 Bakery, 1-31 Aug 2026. Basis EX VAT.
A17: Estimated cost only — not an official value.
